[2024-05-17 23:31:51,945] {taskinstance.py:826} INFO - Dependencies all met for <TaskInstance: stock_historic_prices.fill-stock_history 2024-05-17T23:31:48.721646+00:00 [queued]>
[2024-05-17 23:31:51,967] {taskinstance.py:826} INFO - Dependencies all met for <TaskInstance: stock_historic_prices.fill-stock_history 2024-05-17T23:31:48.721646+00:00 [queued]>
[2024-05-17 23:31:51,968] {taskinstance.py:1017} INFO - 
--------------------------------------------------------------------------------
[2024-05-17 23:31:51,970] {taskinstance.py:1018} INFO - Starting attempt 1 of 2
[2024-05-17 23:31:51,971] {taskinstance.py:1019} INFO - 
--------------------------------------------------------------------------------
[2024-05-17 23:31:51,982] {taskinstance.py:1038} INFO - Executing <Task(PythonOperator): fill-stock_history> on 2024-05-17T23:31:48.721646+00:00
[2024-05-17 23:31:51,989] {standard_task_runner.py:51} INFO - Started process 864 to run task
[2024-05-17 23:31:51,996] {standard_task_runner.py:75} INFO - Running: ['airflow', 'tasks', 'run', 'stock_historic_prices', 'fill-stock_history', '2024-05-17T23:31:48.721646+00:00', '--job-id', '6', '--pool', 'default_pool', '--raw', '--subdir', 'DAGS_FOLDER/stock_historic_prices.py', '--cfg-path', '/tmp/tmpuwto3me9']
[2024-05-17 23:31:52,006] {standard_task_runner.py:76} INFO - Job 6: Subtask fill-stock_history
[2024-05-17 23:31:52,073] {logging_mixin.py:103} INFO - Running <TaskInstance: stock_historic_prices.fill-stock_history 2024-05-17T23:31:48.721646+00:00 [running]> on host 6b6a50b197a8
[2024-05-17 23:31:52,125] {taskinstance.py:1232} INFO - Exporting the following env vars:
AIRFLOW_CTX_DAG_OWNER=airflow
AIRFLOW_CTX_DAG_ID=stock_historic_prices
AIRFLOW_CTX_TASK_ID=fill-stock_history
AIRFLOW_CTX_EXECUTION_DATE=2024-05-17T23:31:48.721646+00:00
AIRFLOW_CTX_DAG_RUN_ID=manual__2024-05-17T23:31:48.721646+00:00
[2024-05-17 23:31:52,131] {logging_mixin.py:103} INFO - Conexión exitosa a PostgreSQL
[2024-05-17 23:32:31,018] {logging_mixin.py:103} INFO - Error al ejecutar la consulta de insert: server closed the connection unexpectedly
	This probably means the server terminated abnormally
	before or while processing the request.
[2024-05-17 23:32:31,025] {logging_mixin.py:103} INFO - 
[2024-05-17 23:32:31,617] {logging_mixin.py:103} INFO - Desconexión exitosa de PostgreSQL
[2024-05-17 23:32:32,149] {python.py:118} INFO - Done. Returned value was: None
[2024-05-17 23:32:32,275] {taskinstance.py:1142} INFO - Marking task as SUCCESS. dag_id=stock_historic_prices, task_id=fill-stock_history, execution_date=20240517T233148, start_date=20240517T233151, end_date=20240517T233232
[2024-05-17 23:32:32,434] {taskinstance.py:1195} INFO - 0 downstream tasks scheduled from follow-on schedule check
[2024-05-17 23:32:32,523] {local_task_job.py:118} INFO - Task exited with return code 0
